2023-06-01 12:54:25,219 INFO    StreamThr :8872 [internal.py:wandb_internal():86] W&B internal server running at pid: 8872, started at: 2023-06-01 12:54:25.218815
2023-06-01 12:54:25,220 DEBUG   HandlerThread:8872 [handler.py:handle_request():144] handle_request: status
2023-06-01 12:54:25,228 INFO    WriterThread:8872 [datastore.py:open_for_write():85] open: C:\Users\Hamid Jahani\Documents\MLOps-Zoomcamp-Course\02-experiment-tracking\Wandb\wandb\run-20230601_125425-balkkxbx\run-balkkxbx.wandb
2023-06-01 12:54:25,228 DEBUG   SenderThread:8872 [sender.py:send():375] send: header
2023-06-01 12:54:25,266 DEBUG   SenderThread:8872 [sender.py:send():375] send: run
2023-06-01 12:54:26,598 ERROR   SenderThread:8872 [internal_api.py:execute():288] 403 response executing GraphQL.
2023-06-01 12:54:26,598 ERROR   SenderThread:8872 [internal_api.py:execute():289] 
<html><head>
<meta http-equiv="content-type" content="text/html;charset=utf-8">
<title>403 Forbidden</title>
</head>
<body text=#000000 bgcolor=#ffffff>
<h1>Error: Forbidden</h1>
<h2>Your client does not have permission to get URL <code>/graphql</code> from this server.</h2>
<h2></h2>
</body></html>

2023-06-01 12:54:26,598 ERROR   SenderThread:8872 [sender.py:send_run():979] It appears that you do not have permission to access the requested resource. Please reach out to the project owner to grant you access. If you have the correct permissions, verify that there are no issues with your networking setup.(Error 403: Forbidden)
Traceback (most recent call last):
  File "C:\Users\Hamid Jahani\AppData\Roaming\Python\Python310\site-packages\wandb\sdk\lib\retry.py", line 131, in __call__
    result = self._call_fn(*args, **kwargs)
  File "C:\Users\Hamid Jahani\AppData\Roaming\Python\Python310\site-packages\wandb\sdk\internal\internal_api.py", line 285, in execute
    return self.client.execute(*args, **kwargs)  # type: ignore
  File "C:\Users\Hamid Jahani\AppData\Roaming\Python\Python310\site-packages\wandb\vendor\gql-0.2.0\wandb_gql\client.py", line 52, in execute
    result = self._get_result(document, *args, **kwargs)
  File "C:\Users\Hamid Jahani\AppData\Roaming\Python\Python310\site-packages\wandb\vendor\gql-0.2.0\wandb_gql\client.py", line 60, in _get_result
    return self.transport.execute(document, *args, **kwargs)
  File "C:\Users\Hamid Jahani\AppData\Roaming\Python\Python310\site-packages\wandb\sdk\lib\gql_request.py", line 56, in execute
    request.raise_for_status()
  File "C:\ProgramData\anaconda3\lib\site-packages\requests\models.py", line 1021, in raise_for_status
    raise HTTPError(http_error_msg, response=self)
requests.exceptions.HTTPError: 403 Client Error: Forbidden for url: https://api.wandb.ai/graphql

During handling of the above exception, another exception occurred:

Traceback (most recent call last):
  File "C:\Users\Hamid Jahani\AppData\Roaming\Python\Python310\site-packages\wandb\sdk\internal\sender.py", line 977, in send_run
    self._init_run(run, config_value_dict)
  File "C:\Users\Hamid Jahani\AppData\Roaming\Python\Python310\site-packages\wandb\sdk\internal\sender.py", line 1015, in _init_run
    server_run, inserted, server_messages = self._api.upsert_run(
  File "C:\Users\Hamid Jahani\AppData\Roaming\Python\Python310\site-packages\wandb\apis\normalize.py", line 73, in wrapper
    raise err
  File "C:\Users\Hamid Jahani\AppData\Roaming\Python\Python310\site-packages\wandb\apis\normalize.py", line 41, in wrapper
    return func(*args, **kwargs)
  File "C:\Users\Hamid Jahani\AppData\Roaming\Python\Python310\site-packages\wandb\sdk\internal\internal_api.py", line 1633, in upsert_run
    self.server_settings_introspection()
  File "C:\Users\Hamid Jahani\AppData\Roaming\Python\Python310\site-packages\wandb\apis\normalize.py", line 73, in wrapper
    raise err
  File "C:\Users\Hamid Jahani\AppData\Roaming\Python\Python310\site-packages\wandb\apis\normalize.py", line 41, in wrapper
    return func(*args, **kwargs)
  File "C:\Users\Hamid Jahani\AppData\Roaming\Python\Python310\site-packages\wandb\sdk\internal\internal_api.py", line 498, in server_settings_introspection
    res = self.gql(query)
  File "C:\Users\Hamid Jahani\AppData\Roaming\Python\Python310\site-packages\wandb\sdk\internal\internal_api.py", line 257, in gql
    ret = self._retry_gql(
  File "C:\Users\Hamid Jahani\AppData\Roaming\Python\Python310\site-packages\wandb\sdk\lib\retry.py", line 147, in __call__
    retry_timedelta_triggered = check_retry_fn(e)
  File "C:\Users\Hamid Jahani\AppData\Roaming\Python\Python310\site-packages\wandb\util.py", line 849, in no_retry_auth
    raise CommError(
wandb.errors.CommError: It appears that you do not have permission to access the requested resource. Please reach out to the project owner to grant you access. If you have the correct permissions, verify that there are no issues with your networking setup.(Error 403: Forbidden)
2023-06-01 12:54:28,628 DEBUG   HandlerThread:8872 [handler.py:handle_request():144] handle_request: shutdown
2023-06-01 12:54:28,628 INFO    HandlerThread:8872 [handler.py:finish():842] shutting down handler
2023-06-01 12:54:29,268 INFO    WriterThread:8872 [datastore.py:close():298] close: C:\Users\Hamid Jahani\Documents\MLOps-Zoomcamp-Course\02-experiment-tracking\Wandb\wandb\run-20230601_125425-balkkxbx\run-balkkxbx.wandb
2023-06-01 12:54:29,603 INFO    SenderThread:8872 [sender.py:finish():1550] shutting down sender
